[2017-07-05 15:16:51 -0400] [44557] [ERROR] Exception in worker process:
Traceback (most recent call last):
  File "/anaconda/envs/py27/lib/python2.7/site-packages/gunicorn/arbiter.py", line 515, in spawn_worker
    worker.init_process()
  File "/anaconda/envs/py27/lib/python2.7/site-packages/gunicorn/workers/base.py", line 122, in init_process
    self.load_wsgi()
  File "/anaconda/envs/py27/lib/python2.7/site-packages/gunicorn/workers/base.py", line 130, in load_wsgi
    self.wsgi = self.app.wsgi()
  File "/anaconda/envs/py27/lib/python2.7/site-packages/gunicorn/app/base.py", line 67, in wsgi
    self.callable = self.load()
  File "/anaconda/envs/py27/lib/python2.7/site-packages/psiturk/experiment_server.py", line 47, in load
    return util.import_app("psiturk.experiment:app")
  File "/anaconda/envs/py27/lib/python2.7/site-packages/gunicorn/util.py", line 357, in import_app
    __import__(module)
  File "/anaconda/envs/py27/lib/python2.7/site-packages/psiturk/experiment.py", line 87, in <module>
    init_db()
  File "/anaconda/envs/py27/lib/python2.7/site-packages/psiturk/db.py", line 37, in init_db
    Base.metadata.create_all(bind=engine)
  File "/anaconda/envs/py27/lib/python2.7/site-packages/sqlalchemy/schema.py", line 2848, in create_all
    tables=tables)
  File "/anaconda/envs/py27/lib/python2.7/site-packages/sqlalchemy/engine/base.py", line 1479, in _run_visitor
    conn._run_visitor(visitorcallable, element, **kwargs)
  File "/anaconda/envs/py27/lib/python2.7/site-packages/sqlalchemy/engine/base.py", line 1122, in _run_visitor
    **kwargs).traverse_single(element)
  File "/anaconda/envs/py27/lib/python2.7/site-packages/sqlalchemy/sql/visitors.py", line 122, in traverse_single
    return meth(obj, **kw)
  File "/anaconda/envs/py27/lib/python2.7/site-packages/sqlalchemy/engine/ddl.py", line 70, in visit_metadata
    self.traverse_single(table, create_ok=True)
  File "/anaconda/envs/py27/lib/python2.7/site-packages/sqlalchemy/sql/visitors.py", line 122, in traverse_single
    return meth(obj, **kw)
  File "/anaconda/envs/py27/lib/python2.7/site-packages/sqlalchemy/engine/ddl.py", line 89, in visit_table
    self.connection.execute(schema.CreateTable(table))
  File "/anaconda/envs/py27/lib/python2.7/site-packages/sqlalchemy/engine/base.py", line 662, in execute
    params)
  File "/anaconda/envs/py27/lib/python2.7/site-packages/sqlalchemy/engine/base.py", line 720, in _execute_ddl
    compiled
  File "/anaconda/envs/py27/lib/python2.7/site-packages/sqlalchemy/engine/base.py", line 874, in _execute_context
    context)
  File "/anaconda/envs/py27/lib/python2.7/site-packages/sqlalchemy/engine/base.py", line 1024, in _handle_dbapi_exception
    exc_info
  File "/anaconda/envs/py27/lib/python2.7/site-packages/sqlalchemy/util/compat.py", line 196, in raise_from_cause
    reraise(type(exception), exception, tb=exc_tb)
  File "/anaconda/envs/py27/lib/python2.7/site-packages/sqlalchemy/engine/base.py", line 867, in _execute_context
    context)
  File "/anaconda/envs/py27/lib/python2.7/site-packages/sqlalchemy/engine/default.py", line 324, in do_execute
    cursor.execute(statement, parameters)
OperationalError: (OperationalError) table turkdemo already exists u'\nCREATE TABLE turkdemo (\n\tuniqueid VARCHAR(128) NOT NULL, \n\tassignmentid VARCHAR(128) NOT NULL, \n\tworkerid VARCHAR(128) NOT NULL, \n\thitid VARCHAR(128) NOT NULL, \n\tipaddress VARCHAR(128), \n\tbrowser VARCHAR(128), \n\tplatform VARCHAR(128), \n\tlanguage VARCHAR(128), \n\tcond INTEGER, \n\tcounterbalance INTEGER, \n\tcodeversion VARCHAR(128), \n\tbeginhit DATETIME, \n\tbeginexp DATETIME, \n\tendhit DATETIME, \n\tbonus FLOAT, \n\tstatus INTEGER, \n\tdatastring TEXT(4294967295), \n\tPRIMARY KEY (uniqueid)\n)\n\n' ()
Traceback (most recent call last):
  File "/anaconda/envs/py27/lib/python2.7/site-packages/gunicorn/arbiter.py", line 515, in spawn_worker
    worker.init_process()
  File "/anaconda/envs/py27/lib/python2.7/site-packages/gunicorn/workers/base.py", line 122, in init_process
    self.load_wsgi()
  File "/anaconda/envs/py27/lib/python2.7/site-packages/gunicorn/workers/base.py", line 130, in load_wsgi
    self.wsgi = self.app.wsgi()
  File "/anaconda/envs/py27/lib/python2.7/site-packages/gunicorn/app/base.py", line 67, in wsgi
    self.callable = self.load()
  File "/anaconda/envs/py27/lib/python2.7/site-packages/psiturk/experiment_server.py", line 47, in load
    return util.import_app("psiturk.experiment:app")
  File "/anaconda/envs/py27/lib/python2.7/site-packages/gunicorn/util.py", line 357, in import_app
    __import__(module)
  File "/anaconda/envs/py27/lib/python2.7/site-packages/psiturk/experiment.py", line 87, in <module>
    init_db()
  File "/anaconda/envs/py27/lib/python2.7/site-packages/psiturk/db.py", line 37, in init_db
    Base.metadata.create_all(bind=engine)
  File "/anaconda/envs/py27/lib/python2.7/site-packages/sqlalchemy/schema.py", line 2848, in create_all
    tables=tables)
  File "/anaconda/envs/py27/lib/python2.7/site-packages/sqlalchemy/engine/base.py", line 1479, in _run_visitor
    conn._run_visitor(visitorcallable, element, **kwargs)
  File "/anaconda/envs/py27/lib/python2.7/site-packages/sqlalchemy/engine/base.py", line 1122, in _run_visitor
    **kwargs).traverse_single(element)
  File "/anaconda/envs/py27/lib/python2.7/site-packages/sqlalchemy/sql/visitors.py", line 122, in traverse_single
    return meth(obj, **kw)
  File "/anaconda/envs/py27/lib/python2.7/site-packages/sqlalchemy/engine/ddl.py", line 70, in visit_metadata
    self.traverse_single(table, create_ok=True)
  File "/anaconda/envs/py27/lib/python2.7/site-packages/sqlalchemy/sql/visitors.py", line 122, in traverse_single
    return meth(obj, **kw)
  File "/anaconda/envs/py27/lib/python2.7/site-packages/sqlalchemy/engine/ddl.py", line 89, in visit_table
    self.connection.execute(schema.CreateTable(table))
  File "/anaconda/envs/py27/lib/python2.7/site-packages/sqlalchemy/engine/base.py", line 662, in execute
    params)
  File "/anaconda/envs/py27/lib/python2.7/site-packages/sqlalchemy/engine/base.py", line 720, in _execute_ddl
    compiled
  File "/anaconda/envs/py27/lib/python2.7/site-packages/sqlalchemy/engine/base.py", line 874, in _execute_context
    context)
  File "/anaconda/envs/py27/lib/python2.7/site-packages/sqlalchemy/engine/base.py", line 1024, in _handle_dbapi_exception
    exc_info
  File "/anaconda/envs/py27/lib/python2.7/site-packages/sqlalchemy/util/compat.py", line 196, in raise_from_cause
    reraise(type(exception), exception, tb=exc_tb)
  File "/anaconda/envs/py27/lib/python2.7/site-packages/sqlalchemy/engine/base.py", line 867, in _execute_context
    context)
  File "/anaconda/envs/py27/lib/python2.7/site-packages/sqlalchemy/engine/default.py", line 324, in do_execute
    cursor.execute(statement, parameters)
OperationalError: (OperationalError) table turkdemo already exists u'\nCREATE TABLE turkdemo (\n\tuniqueid VARCHAR(128) NOT NULL, \n\tassignmentid VARCHAR(128) NOT NULL, \n\tworkerid VARCHAR(128) NOT NULL, \n\thitid VARCHAR(128) NOT NULL, \n\tipaddress VARCHAR(128), \n\tbrowser VARCHAR(128), \n\tplatform VARCHAR(128), \n\tlanguage VARCHAR(128), \n\tcond INTEGER, \n\tcounterbalance INTEGER, \n\tcodeversion VARCHAR(128), \n\tbeginhit DATETIME, \n\tbeginexp DATETIME, \n\tendhit DATETIME, \n\tbonus FLOAT, \n\tstatus INTEGER, \n\tdatastring TEXT(4294967295), \n\tPRIMARY KEY (uniqueid)\n)\n\n' ()
[2017-10-12 16:54:00 -0400] [68694] [CRITICAL] WORKER TIMEOUT (pid:68704)
[2017-10-12 16:54:00 -0400] [68694] [CRITICAL] WORKER TIMEOUT (pid:68705)
[2017-10-12 16:54:00 -0400] [68694] [CRITICAL] WORKER TIMEOUT (pid:68706)
[2017-10-12 16:54:00 -0400] [68694] [CRITICAL] WORKER TIMEOUT (pid:68698)
[2017-10-12 16:54:00 -0400] [68694] [CRITICAL] WORKER TIMEOUT (pid:68699)
[2017-10-12 16:54:00 -0400] [68694] [CRITICAL] WORKER TIMEOUT (pid:68700)
[2017-10-12 16:54:00 -0400] [68694] [CRITICAL] WORKER TIMEOUT (pid:68701)
[2017-10-12 16:54:00 -0400] [68694] [CRITICAL] WORKER TIMEOUT (pid:68702)
[2017-10-12 16:54:00 -0400] [68694] [CRITICAL] WORKER TIMEOUT (pid:68703)
2017-10-29 15:52:46,627 Exception on /submit.html [GET]
Traceback (most recent call last):
  File "/anaconda/envs/py27/lib/python2.7/site-packages/flask/app.py", line 1817, in wsgi_app
    response = self.full_dispatch_request()
  File "/anaconda/envs/py27/lib/python2.7/site-packages/flask/app.py", line 1477, in full_dispatch_request
    rv = self.handle_user_exception(e)
  File "/anaconda/envs/py27/lib/python2.7/site-packages/flask/app.py", line 1381, in handle_user_exception
    reraise(exc_type, exc_value, tb)
  File "/anaconda/envs/py27/lib/python2.7/site-packages/flask/app.py", line 1475, in full_dispatch_request
    rv = self.dispatch_request()
  File "/anaconda/envs/py27/lib/python2.7/site-packages/flask/app.py", line 1461, in dispatch_request
    return self.view_functions[rule.endpoint](**req.view_args)
  File "/anaconda/envs/py27/lib/python2.7/site-packages/psiturk/experiment.py", line 713, in regularpage
    return render_template(pagename)
  File "/anaconda/envs/py27/lib/python2.7/site-packages/flask/templating.py", line 127, in render_template
    return _render(ctx.app.jinja_env.get_or_select_template(template_name_or_list),
  File "/anaconda/envs/py27/lib/python2.7/site-packages/jinja2/environment.py", line 869, in get_or_select_template
    return self.get_template(template_name_or_list, parent, globals)
  File "/anaconda/envs/py27/lib/python2.7/site-packages/jinja2/environment.py", line 830, in get_template
    return self._load_template(name, self.make_globals(globals))
  File "/anaconda/envs/py27/lib/python2.7/site-packages/jinja2/environment.py", line 804, in _load_template
    template = self.loader.load(self, name, globals)
  File "/anaconda/envs/py27/lib/python2.7/site-packages/jinja2/loaders.py", line 113, in load
    source, filename, uptodate = self.get_source(environment, name)
  File "/anaconda/envs/py27/lib/python2.7/site-packages/flask/templating.py", line 64, in get_source
    raise TemplateNotFound(template)
TemplateNotFound: submit.html
2017-10-29 15:54:45,188 Exception on /submit.html [GET]
Traceback (most recent call last):
  File "/anaconda/envs/py27/lib/python2.7/site-packages/flask/app.py", line 1817, in wsgi_app
    response = self.full_dispatch_request()
  File "/anaconda/envs/py27/lib/python2.7/site-packages/flask/app.py", line 1477, in full_dispatch_request
    rv = self.handle_user_exception(e)
  File "/anaconda/envs/py27/lib/python2.7/site-packages/flask/app.py", line 1381, in handle_user_exception
    reraise(exc_type, exc_value, tb)
  File "/anaconda/envs/py27/lib/python2.7/site-packages/flask/app.py", line 1475, in full_dispatch_request
    rv = self.dispatch_request()
  File "/anaconda/envs/py27/lib/python2.7/site-packages/flask/app.py", line 1461, in dispatch_request
    return self.view_functions[rule.endpoint](**req.view_args)
  File "/anaconda/envs/py27/lib/python2.7/site-packages/psiturk/experiment.py", line 713, in regularpage
    return render_template(pagename)
  File "/anaconda/envs/py27/lib/python2.7/site-packages/flask/templating.py", line 127, in render_template
    return _render(ctx.app.jinja_env.get_or_select_template(template_name_or_list),
  File "/anaconda/envs/py27/lib/python2.7/site-packages/jinja2/environment.py", line 869, in get_or_select_template
    return self.get_template(template_name_or_list, parent, globals)
  File "/anaconda/envs/py27/lib/python2.7/site-packages/jinja2/environment.py", line 830, in get_template
    return self._load_template(name, self.make_globals(globals))
  File "/anaconda/envs/py27/lib/python2.7/site-packages/jinja2/environment.py", line 804, in _load_template
    template = self.loader.load(self, name, globals)
  File "/anaconda/envs/py27/lib/python2.7/site-packages/jinja2/loaders.py", line 113, in load
    source, filename, uptodate = self.get_source(environment, name)
  File "/anaconda/envs/py27/lib/python2.7/site-packages/flask/templating.py", line 64, in get_source
    raise TemplateNotFound(template)
TemplateNotFound: submit.html
2017-10-29 15:56:31,256 Exception on /submit.html [GET]
Traceback (most recent call last):
  File "/anaconda/envs/py27/lib/python2.7/site-packages/flask/app.py", line 1817, in wsgi_app
    response = self.full_dispatch_request()
  File "/anaconda/envs/py27/lib/python2.7/site-packages/flask/app.py", line 1477, in full_dispatch_request
    rv = self.handle_user_exception(e)
  File "/anaconda/envs/py27/lib/python2.7/site-packages/flask/app.py", line 1381, in handle_user_exception
    reraise(exc_type, exc_value, tb)
  File "/anaconda/envs/py27/lib/python2.7/site-packages/flask/app.py", line 1475, in full_dispatch_request
    rv = self.dispatch_request()
  File "/anaconda/envs/py27/lib/python2.7/site-packages/flask/app.py", line 1461, in dispatch_request
    return self.view_functions[rule.endpoint](**req.view_args)
  File "/anaconda/envs/py27/lib/python2.7/site-packages/psiturk/experiment.py", line 713, in regularpage
    return render_template(pagename)
  File "/anaconda/envs/py27/lib/python2.7/site-packages/flask/templating.py", line 127, in render_template
    return _render(ctx.app.jinja_env.get_or_select_template(template_name_or_list),
  File "/anaconda/envs/py27/lib/python2.7/site-packages/jinja2/environment.py", line 869, in get_or_select_template
    return self.get_template(template_name_or_list, parent, globals)
  File "/anaconda/envs/py27/lib/python2.7/site-packages/jinja2/environment.py", line 830, in get_template
    return self._load_template(name, self.make_globals(globals))
  File "/anaconda/envs/py27/lib/python2.7/site-packages/jinja2/environment.py", line 804, in _load_template
    template = self.loader.load(self, name, globals)
  File "/anaconda/envs/py27/lib/python2.7/site-packages/jinja2/loaders.py", line 113, in load
    source, filename, uptodate = self.get_source(environment, name)
  File "/anaconda/envs/py27/lib/python2.7/site-packages/flask/templating.py", line 64, in get_source
    raise TemplateNotFound(template)
TemplateNotFound: submit.html
2017-10-29 16:00:52,939 Exception on /submit.html [GET]
Traceback (most recent call last):
  File "/anaconda/envs/py27/lib/python2.7/site-packages/flask/app.py", line 1817, in wsgi_app
    response = self.full_dispatch_request()
  File "/anaconda/envs/py27/lib/python2.7/site-packages/flask/app.py", line 1477, in full_dispatch_request
    rv = self.handle_user_exception(e)
  File "/anaconda/envs/py27/lib/python2.7/site-packages/flask/app.py", line 1381, in handle_user_exception
    reraise(exc_type, exc_value, tb)
  File "/anaconda/envs/py27/lib/python2.7/site-packages/flask/app.py", line 1475, in full_dispatch_request
    rv = self.dispatch_request()
  File "/anaconda/envs/py27/lib/python2.7/site-packages/flask/app.py", line 1461, in dispatch_request
    return self.view_functions[rule.endpoint](**req.view_args)
  File "/anaconda/envs/py27/lib/python2.7/site-packages/psiturk/experiment.py", line 713, in regularpage
    return render_template(pagename)
  File "/anaconda/envs/py27/lib/python2.7/site-packages/flask/templating.py", line 127, in render_template
    return _render(ctx.app.jinja_env.get_or_select_template(template_name_or_list),
  File "/anaconda/envs/py27/lib/python2.7/site-packages/jinja2/environment.py", line 869, in get_or_select_template
    return self.get_template(template_name_or_list, parent, globals)
  File "/anaconda/envs/py27/lib/python2.7/site-packages/jinja2/environment.py", line 830, in get_template
    return self._load_template(name, self.make_globals(globals))
  File "/anaconda/envs/py27/lib/python2.7/site-packages/jinja2/environment.py", line 804, in _load_template
    template = self.loader.load(self, name, globals)
  File "/anaconda/envs/py27/lib/python2.7/site-packages/jinja2/loaders.py", line 113, in load
    source, filename, uptodate = self.get_source(environment, name)
  File "/anaconda/envs/py27/lib/python2.7/site-packages/flask/templating.py", line 64, in get_source
    raise TemplateNotFound(template)
TemplateNotFound: submit.html
2017-11-02 15:48:54,327 Exception on /submit.html [GET]
Traceback (most recent call last):
  File "/anaconda/envs/py27/lib/python2.7/site-packages/flask/app.py", line 1817, in wsgi_app
    response = self.full_dispatch_request()
  File "/anaconda/envs/py27/lib/python2.7/site-packages/flask/app.py", line 1477, in full_dispatch_request
    rv = self.handle_user_exception(e)
  File "/anaconda/envs/py27/lib/python2.7/site-packages/flask/app.py", line 1381, in handle_user_exception
    reraise(exc_type, exc_value, tb)
  File "/anaconda/envs/py27/lib/python2.7/site-packages/flask/app.py", line 1475, in full_dispatch_request
    rv = self.dispatch_request()
  File "/anaconda/envs/py27/lib/python2.7/site-packages/flask/app.py", line 1461, in dispatch_request
    return self.view_functions[rule.endpoint](**req.view_args)
  File "/anaconda/envs/py27/lib/python2.7/site-packages/psiturk/experiment.py", line 713, in regularpage
    return render_template(pagename)
  File "/anaconda/envs/py27/lib/python2.7/site-packages/flask/templating.py", line 127, in render_template
    return _render(ctx.app.jinja_env.get_or_select_template(template_name_or_list),
  File "/anaconda/envs/py27/lib/python2.7/site-packages/jinja2/environment.py", line 869, in get_or_select_template
    return self.get_template(template_name_or_list, parent, globals)
  File "/anaconda/envs/py27/lib/python2.7/site-packages/jinja2/environment.py", line 830, in get_template
    return self._load_template(name, self.make_globals(globals))
  File "/anaconda/envs/py27/lib/python2.7/site-packages/jinja2/environment.py", line 804, in _load_template
    template = self.loader.load(self, name, globals)
  File "/anaconda/envs/py27/lib/python2.7/site-packages/jinja2/loaders.py", line 113, in load
    source, filename, uptodate = self.get_source(environment, name)
  File "/anaconda/envs/py27/lib/python2.7/site-packages/flask/templating.py", line 64, in get_source
    raise TemplateNotFound(template)
TemplateNotFound: submit.html
2017-11-02 15:51:41,219 Exception on /submit.html [GET]
Traceback (most recent call last):
  File "/anaconda/envs/py27/lib/python2.7/site-packages/flask/app.py", line 1817, in wsgi_app
    response = self.full_dispatch_request()
  File "/anaconda/envs/py27/lib/python2.7/site-packages/flask/app.py", line 1477, in full_dispatch_request
    rv = self.handle_user_exception(e)
  File "/anaconda/envs/py27/lib/python2.7/site-packages/flask/app.py", line 1381, in handle_user_exception
    reraise(exc_type, exc_value, tb)
  File "/anaconda/envs/py27/lib/python2.7/site-packages/flask/app.py", line 1475, in full_dispatch_request
    rv = self.dispatch_request()
  File "/anaconda/envs/py27/lib/python2.7/site-packages/flask/app.py", line 1461, in dispatch_request
    return self.view_functions[rule.endpoint](**req.view_args)
  File "/anaconda/envs/py27/lib/python2.7/site-packages/psiturk/experiment.py", line 713, in regularpage
    return render_template(pagename)
  File "/anaconda/envs/py27/lib/python2.7/site-packages/flask/templating.py", line 127, in render_template
    return _render(ctx.app.jinja_env.get_or_select_template(template_name_or_list),
  File "/anaconda/envs/py27/lib/python2.7/site-packages/jinja2/environment.py", line 869, in get_or_select_template
    return self.get_template(template_name_or_list, parent, globals)
  File "/anaconda/envs/py27/lib/python2.7/site-packages/jinja2/environment.py", line 830, in get_template
    return self._load_template(name, self.make_globals(globals))
  File "/anaconda/envs/py27/lib/python2.7/site-packages/jinja2/environment.py", line 804, in _load_template
    template = self.loader.load(self, name, globals)
  File "/anaconda/envs/py27/lib/python2.7/site-packages/jinja2/loaders.py", line 113, in load
    source, filename, uptodate = self.get_source(environment, name)
  File "/anaconda/envs/py27/lib/python2.7/site-packages/flask/templating.py", line 64, in get_source
    raise TemplateNotFound(template)
TemplateNotFound: submit.html
[2017-11-07 17:34:09 -0500] [38958] [CRITICAL] WORKER TIMEOUT (pid:38964)
[2017-11-07 17:34:09 -0500] [38958] [CRITICAL] WORKER TIMEOUT (pid:38965)
[2017-11-07 17:34:09 -0500] [38958] [CRITICAL] WORKER TIMEOUT (pid:38966)
[2017-11-07 17:34:09 -0500] [38958] [CRITICAL] WORKER TIMEOUT (pid:38967)
[2017-11-07 17:34:09 -0500] [38958] [CRITICAL] WORKER TIMEOUT (pid:38968)
[2017-11-07 17:34:09 -0500] [38958] [CRITICAL] WORKER TIMEOUT (pid:38969)
[2017-11-07 17:34:09 -0500] [38958] [CRITICAL] WORKER TIMEOUT (pid:38970)
[2017-11-07 17:34:09 -0500] [38958] [CRITICAL] WORKER TIMEOUT (pid:38971)
[2017-11-07 17:34:09 -0500] [38958] [CRITICAL] WORKER TIMEOUT (pid:38972)
